module,execution_time (sec),success,timestamp,error,error_short
cowidev.vax.batch.argentina,14.16,True,2023-03-23T07:00:20,,
cowidev.vax.batch.australia,0.23,False,2023-03-23T07:01:48,"Traceback (most recent call last):
  File ""/home/owid/covid-19-data/scripts/src/cowidev/cmd/commons/get.py"", line 47, in run
    module.main()
  File ""/home/owid/covid-19-data/scripts/src/cowidev/vax/batch/australia.py"", line 244, in main
    Australia().export()
  File ""/home/owid/covid-19-data/scripts/src/cowidev/vax/batch/australia.py"", line 216, in export
    df = self.read().pipe(self.pipeline)  # Use with attach=False
  File ""/home/owid/covid-19-data/scripts/venv/lib/python3.10/site-packages/pandas/core/generic.py"", line 5430, in pipe
    return com.pipe(self, func, *args, **kwargs)
  File ""/home/owid/covid-19-data/scripts/venv/lib/python3.10/site-packages/pandas/core/common.py"", line 471, in pipe
    return func(obj, *args, **kwargs)
  File ""/home/owid/covid-19-data/scripts/src/cowidev/vax/batch/australia.py"", line 160, in pipeline
    .pipe(self.make_monotonic)
  File ""/home/owid/covid-19-data/scripts/venv/lib/python3.10/site-packages/pandas/core/generic.py"", line 5430, in pipe
    return com.pipe(self, func, *args, **kwargs)
  File ""/home/owid/covid-19-data/scripts/venv/lib/python3.10/site-packages/pandas/core/common.py"", line 471, in pipe
    return func(obj, *args, **kwargs)
  File ""/home/owid/covid-19-data/scripts/src/cowidev/vax/utils/base.py"", line 120, in make_monotonic
    return mkm(
  File ""/home/owid/covid-19-data/scripts/src/cowidev/utils/utils.py"", line 23, in make_monotonic
    return make_monotonic_new(df, column_date, column_metrics, max_removed_rows)
  File ""/home/owid/covid-19-data/scripts/src/cowidev/utils/utils.py"", line 94, in make_monotonic_new
    raise Exception(
Exception: 1 chunks of lengths 18 have been NaNed for metric people_vaccinated. That is more than maximum allowed (10) by make_monotonic() - check the data. Check dates ['2023-03-09']
",1 chunks of lengths 18 have been NaNed for metric people_vaccinated. That is more than maximum allowed (10) by make_monotonic() - check the data. Check dates ['2023-03-09']
cowidev.vax.batch.austria_old,,,2023-03-23T07:00:06,,
cowidev.vax.batch.belgium,9.27,True,2023-03-23T07:00:15,,
cowidev.vax.batch.bolivia,4.42,True,2023-03-23T07:00:10,,
cowidev.vax.batch.canada,5.19,False,2023-03-23T07:01:53,"Traceback (most recent call last):
  File ""/home/owid/covid-19-data/scripts/src/cowidev/cmd/commons/get.py"", line 47, in run
    module.main()
  File ""/home/owid/covid-19-data/scripts/src/cowidev/vax/batch/canada.py"", line 282, in main
    Canada().export()
  File ""/home/owid/covid-19-data/scripts/src/cowidev/vax/batch/canada.py"", line 270, in export
    df = df.pipe(self.pipeline, df_man)
  File ""/home/owid/covid-19-data/scripts/venv/lib/python3.10/site-packages/pandas/core/generic.py"", line 5430, in pipe
    return com.pipe(self, func, *args, **kwargs)
  File ""/home/owid/covid-19-data/scripts/venv/lib/python3.10/site-packages/pandas/core/common.py"", line 471, in pipe
    return func(obj, *args, **kwargs)
  File ""/home/owid/covid-19-data/scripts/src/cowidev/vax/batch/canada.py"", line 250, in pipeline
    .pipe(self.pipe_make_monotonic)[
  File ""/home/owid/covid-19-data/scripts/venv/lib/python3.10/site-packages/pandas/core/generic.py"", line 5430, in pipe
    return com.pipe(self, func, *args, **kwargs)
  File ""/home/owid/covid-19-data/scripts/venv/lib/python3.10/site-packages/pandas/core/common.py"", line 471, in pipe
    return func(obj, *args, **kwargs)
  File ""/home/owid/covid-19-data/scripts/src/cowidev/vax/batch/canada.py"", line 230, in pipe_make_monotonic
    df = df.pipe(self.make_monotonic, max_removed_rows=self.max_removed_rows)
  File ""/home/owid/covid-19-data/scripts/venv/lib/python3.10/site-packages/pandas/core/generic.py"", line 5430, in pipe
    return com.pipe(self, func, *args, **kwargs)
  File ""/home/owid/covid-19-data/scripts/venv/lib/python3.10/site-packages/pandas/core/common.py"", line 471, in pipe
    return func(obj, *args, **kwargs)
  File ""/home/owid/covid-19-data/scripts/src/cowidev/vax/utils/base.py"", line 120, in make_monotonic
    return mkm(
  File ""/home/owid/covid-19-data/scripts/src/cowidev/utils/utils.py"", line 23, in make_monotonic
    return make_monotonic_new(df, column_date, column_metrics, max_removed_rows)
  File ""/home/owid/covid-19-data/scripts/src/cowidev/utils/utils.py"", line 94, in make_monotonic_new
    raise Exception(
Exception: 1 chunks of lengths 36 have been NaNed for metric people_vaccinated. That is more than maximum allowed (22) by make_monotonic() - check the data. Check dates ['2023-01-26']
",1 chunks of lengths 36 have been NaNed for metric people_vaccinated. That is more than maximum allowed (22) by make_monotonic() - check the data. Check dates ['2023-01-26']
cowidev.vax.batch.chile,1.41,True,2023-03-23T07:00:07,,
cowidev.vax.batch.czechia,25.75,True,2023-03-23T07:00:32,,
cowidev.vax.batch.denmark,73.85,True,2023-03-23T07:01:20,,
cowidev.vax.batch.ecdc,85.57,True,2023-03-23T07:01:31,,
cowidev.vax.batch.ecuador,,,2023-03-23T07:00:06,,
cowidev.vax.batch.estonia,0.66,True,2023-03-23T07:00:07,,
cowidev.vax.batch.france,7.58,True,2023-03-23T07:00:13,,
cowidev.vax.batch.germany,0.18,True,2023-03-23T07:00:06,,
cowidev.vax.batch.greece,15.59,True,2023-03-23T07:00:21,,
cowidev.vax.batch.hong_kong,17.77,True,2023-03-23T07:00:24,,
cowidev.vax.batch.indonesia,,,2023-03-23T07:00:06,,
cowidev.vax.batch.ireland,4.42,True,2023-03-23T07:00:10,,
cowidev.vax.batch.israel,9.67,True,2023-03-23T07:00:16,,
cowidev.vax.batch.italy,9.64,True,2023-03-23T07:00:16,,
cowidev.vax.batch.japan,33.76,True,2023-03-23T07:00:40,,
cowidev.vax.batch.jersey,4.85,True,2023-03-23T07:00:11,,
cowidev.vax.batch.latvia,69.28,True,2023-03-23T07:01:15,,
cowidev.vax.batch.lithuania,4.96,True,2023-03-23T07:00:11,,
cowidev.vax.batch.luxembourg,2.19,True,2023-03-23T07:00:08,,
cowidev.vax.batch.malaysia,1.2,True,2023-03-23T07:00:07,,
cowidev.vax.batch.malta,1.21,True,2023-03-23T07:00:07,,
cowidev.vax.batch.netherlands,,,2023-03-23T07:00:06,,
cowidev.vax.batch.new_zealand,13.25,True,2023-03-23T07:00:19,,
cowidev.vax.batch.norway,1.24,True,2023-03-23T07:00:07,,
cowidev.vax.batch.peru,0.87,True,2023-03-23T07:01:54,,
cowidev.vax.batch.portugal,,,2023-03-23T07:00:06,,
cowidev.vax.batch.romania,30.75,True,2023-03-23T07:00:37,,
cowidev.vax.batch.saudi_arabia,10.15,True,2023-03-23T07:00:16,,
cowidev.vax.batch.singapore,4.77,True,2023-03-23T07:00:11,,
cowidev.vax.batch.slovakia,49.0,True,2023-03-23T07:00:55,,
cowidev.vax.batch.slovenia,2.34,True,2023-03-23T07:00:08,,
cowidev.vax.batch.south_korea,65.57,True,2023-03-23T07:01:12,,
cowidev.vax.batch.spc,27.6,True,2023-03-23T07:00:35,,
cowidev.vax.batch.sweden,15.67,True,2023-03-23T07:00:23,,
cowidev.vax.batch.switzerland,82.91,True,2023-03-23T07:01:30,,
cowidev.vax.batch.trinidad_and_tobago,3.44,True,2023-03-23T07:00:11,,
cowidev.vax.batch.ukraine,,,2023-03-23T07:00:08,,
cowidev.vax.batch.united_kingdom,15.28,True,2023-03-23T07:00:23,,
cowidev.vax.batch.united_states,83.98,True,2023-03-23T07:01:32,,
cowidev.vax.batch.uruguay,7.38,True,2023-03-23T07:00:16,,
cowidev.vax.batch.zimbabwe,3.07,True,2023-03-23T07:00:13,,
cowidev.vax.incremental.africacdc,,,2023-03-23T07:00:10,,
cowidev.vax.incremental.antigua_barbuda,,,2023-03-23T07:00:10,,
cowidev.vax.incremental.aruba,2.86,True,2023-03-23T07:00:13,,
cowidev.vax.incremental.austria,,,2023-03-23T07:00:11,,
cowidev.vax.incremental.azerbaijan,,,2023-03-23T07:00:11,,
cowidev.vax.incremental.bahrain,,,2023-03-23T07:00:11,,
cowidev.vax.incremental.bangladesh,37.08,False,2023-03-23T07:02:31,"Traceback (most recent call last):
  File ""/home/owid/covid-19-data/scripts/venv/lib/python3.10/site-packages/urllib3/response.py"", line 443, in _error_catcher
    yield
  File ""/home/owid/covid-19-data/scripts/venv/lib/python3.10/site-packages/urllib3/response.py"", line 815, in read_chunked
    self._update_chunk_length()
  File ""/home/owid/covid-19-data/scripts/venv/lib/python3.10/site-packages/urllib3/response.py"", line 745, in _update_chunk_length
    line = self._fp.fp.readline()
  File ""/usr/lib/python3.10/socket.py"", line 705, in readinto
    return self._sock.recv_into(b)
TimeoutError: timed out

During handling of the above exception, another exception occurred:

Traceback (most recent call last):
  File ""/home/owid/covid-19-data/scripts/venv/lib/python3.10/site-packages/requests/models.py"", line 760, in generate
    for chunk in self.raw.stream(chunk_size, decode_content=True):
  File ""/home/owid/covid-19-data/scripts/venv/lib/python3.10/site-packages/urllib3/response.py"", line 623, in stream
    for line in self.read_chunked(amt, decode_content=decode_content):
  File ""/home/owid/covid-19-data/scripts/venv/lib/python3.10/site-packages/urllib3/response.py"", line 803, in read_chunked
    with self._error_catcher():
  File ""/usr/lib/python3.10/contextlib.py"", line 153, in __exit__
    self.gen.throw(typ, value, traceback)
  File ""/home/owid/covid-19-data/scripts/venv/lib/python3.10/site-packages/urllib3/response.py"", line 448, in _error_catcher
    raise ReadTimeoutError(self._pool, None, ""Read timed out."")
urllib3.exceptions.ReadTimeoutError: HTTPConnectionPool(host='103.247.238.92', port=80): Read timed out.

During handling of the above exception, another exception occurred:

Traceback (most recent call last):
  File ""/home/owid/covid-19-data/scripts/src/cowidev/cmd/commons/get.py"", line 47, in run
    module.main()
  File ""/home/owid/covid-19-data/scripts/src/cowidev/vax/incremental/bangladesh.py"", line 112, in main
    Bangladesh().export()
  File ""/home/owid/covid-19-data/scripts/src/cowidev/vax/incremental/bangladesh.py"", line 98, in export
    data = self.read().pipe(self.pipeline)
  File ""/home/owid/covid-19-data/scripts/src/cowidev/vax/incremental/bangladesh.py"", line 25, in read
    metrics = self._parse_metrics(soup)
  File ""/home/owid/covid-19-data/scripts/src/cowidev/vax/incremental/bangladesh.py"", line 74, in _parse_metrics
    single_doses = self._parse_single_doses()
  File ""/home/owid/covid-19-data/scripts/src/cowidev/vax/incremental/bangladesh.py"", line 38, in _parse_single_doses
    soup = get_soup(url, timeout=30)
  File ""/home/owid/covid-19-data/scripts/src/cowidev/utils/web/scraping.py"", line 83, in get_soup
    response = get_response(source, request_method, use_proxy, **kwargs)
  File ""/home/owid/covid-19-data/scripts/src/cowidev/utils/web/scraping.py"", line 49, in get_response
    raise err
  File ""/home/owid/covid-19-data/scripts/src/cowidev/utils/web/scraping.py"", line 43, in get_response
    response = requests.get(source, **kwargs)
  File ""/home/owid/covid-19-data/scripts/venv/lib/python3.10/site-packages/requests/api.py"", line 75, in get
    return request('get', url, params=params, **kwargs)
  File ""/home/owid/covid-19-data/scripts/venv/lib/python3.10/site-packages/requests/api.py"", line 61, in request
    return session.request(method=method, url=url, **kwargs)
  File ""/home/owid/covid-19-data/scripts/venv/lib/python3.10/site-packages/requests/sessions.py"", line 529, in request
    resp = self.send(prep, **send_kwargs)
  File ""/home/owid/covid-19-data/scripts/venv/lib/python3.10/site-packages/requests/sessions.py"", line 687, in send
    r.content
  File ""/home/owid/covid-19-data/scripts/venv/lib/python3.10/site-packages/requests/models.py"", line 838, in content
    self._content = b''.join(self.iter_content(CONTENT_CHUNK_SIZE)) or b''
  File ""/home/owid/covid-19-data/scripts/venv/lib/python3.10/site-packages/requests/models.py"", line 767, in generate
    raise ConnectionError(e)
requests.exceptions.ConnectionError: HTTPConnectionPool(host='103.247.238.92', port=80): Read timed out.
","HTTPConnectionPool(host='103.247.238.92', port=80): Read timed out."
cowidev.vax.incremental.barbados,,,2023-03-23T07:00:11,,
cowidev.vax.incremental.brazil,2.3,True,2023-03-23T07:00:13,,
cowidev.vax.incremental.bulgaria,8.5,True,2023-03-23T07:00:19,,
cowidev.vax.incremental.china,17.91,True,2023-03-23T07:00:29,,
cowidev.vax.incremental.costa_rica,,,2023-03-23T07:00:11,,
cowidev.vax.incremental.croatia,2.02,True,2023-03-23T07:00:13,,
cowidev.vax.incremental.cuba,9.64,True,2023-03-23T07:00:23,,
cowidev.vax.incremental.curacao,1.16,True,2023-03-23T07:00:14,,
cowidev.vax.incremental.cyprus,2.39,True,2023-03-23T07:00:16,,
cowidev.vax.incremental.dominican_republic,11.48,False,2023-03-23T07:02:43,"Traceback (most recent call last):
  File ""/home/owid/covid-19-data/scripts/src/cowidev/cmd/commons/get.py"", line 47, in run
    module.main()
  File ""/home/owid/covid-19-data/scripts/src/cowidev/vax/incremental/dominican_republic.py"", line 113, in main
    DominicanRepublic().export()
  File ""/home/owid/covid-19-data/scripts/src/cowidev/vax/incremental/dominican_republic.py"", line 68, in export
    data = self.read().pipe(self.pipeline)
  File ""/home/owid/covid-19-data/scripts/src/cowidev/vax/incremental/dominican_republic.py"", line 26, in read
    metrics = self._parse_metrics(driver)
  File ""/home/owid/covid-19-data/scripts/src/cowidev/vax/incremental/dominican_republic.py"", line 35, in _parse_metrics
    metric_candidates = _find_potential_metrics(driver)
  File ""/home/owid/covid-19-data/scripts/src/cowidev/vax/incremental/dominican_republic.py"", line 92, in _find_potential_metrics
    h3 = _find_h3(driver)
  File ""/home/owid/covid-19-data/scripts/src/cowidev/vax/incremental/dominican_republic.py"", line 82, in _find_h3
    raise ValueError(""More than one element found!"")
ValueError: More than one element found!
",More than one element found!
cowidev.vax.incremental.el_salvador,9.54,True,2023-03-23T07:00:23,,
cowidev.vax.incremental.faeroe_islands,1.48,True,2023-03-23T07:00:16,,
cowidev.vax.incremental.fiji,0.0,True,2023-03-23T07:00:15,,
cowidev.vax.incremental.finland,0.55,True,2023-03-23T07:00:16,,
cowidev.vax.incremental.gabon,,,2023-03-23T07:00:16,,
cowidev.vax.incremental.georgia,7.54,True,2023-03-23T07:00:23,,
cowidev.vax.incremental.greenland,0.09,False,2023-03-23T07:02:43,"Traceback (most recent call last):
  File ""/home/owid/covid-19-data/scripts/src/cowidev/cmd/commons/get.py"", line 47, in run
    module.main()
  File ""/home/owid/covid-19-data/scripts/src/cowidev/vax/incremental/greenland.py"", line 76, in main
    Greenland().export()
  File ""/home/owid/covid-19-data/scripts/src/cowidev/vax/incremental/greenland.py"", line 63, in export
    data = self.read().pipe(self.pipeline)
  File ""/home/owid/covid-19-data/scripts/src/cowidev/vax/incremental/greenland.py"", line 17, in read
    data = self._parse_data(soup)
  File ""/home/owid/covid-19-data/scripts/src/cowidev/vax/incremental/greenland.py"", line 21, in _parse_data
    return {**self._parse_data_metrics(soup), **self._parse_data_date(soup)}
  File ""/home/owid/covid-19-data/scripts/src/cowidev/vax/incremental/greenland.py"", line 31, in _parse_data_metrics
    assert len(counter_1) == len(counter_2) == 1
AssertionError
",
cowidev.vax.incremental.guatemala,,,2023-03-23T07:00:16,,
cowidev.vax.incremental.guernsey,8.37,True,2023-03-23T07:00:24,,
cowidev.vax.incremental.hungary,18.14,True,2023-03-23T07:03:01,,
cowidev.vax.incremental.iceland,2.46,True,2023-03-23T07:00:18,,
cowidev.vax.incremental.india,5.28,True,2023-03-23T07:00:21,,
cowidev.vax.incremental.iran,,,2023-03-23T07:00:16,,
cowidev.vax.incremental.isle_of_man,2.53,True,2023-03-23T07:00:19,,
cowidev.vax.incremental.jamaica,6.65,True,2023-03-23T07:00:25,,
cowidev.vax.incremental.kazakhstan,6.68,True,2023-03-23T07:00:25,,
cowidev.vax.incremental.kosovo,0.12,False,2023-03-23T07:03:01,"Traceback (most recent call last):
  File ""/home/owid/covid-19-data/scripts/src/cowidev/cmd/commons/get.py"", line 47, in run
    module.main()
  File ""/home/owid/covid-19-data/scripts/src/cowidev/vax/incremental/kosovo.py"", line 82, in main
    Kosovo().export()
  File ""/home/owid/covid-19-data/scripts/src/cowidev/vax/incremental/kosovo.py"", line 77, in export
    df = self.read().pipe(self.pipeline)
  File ""/home/owid/covid-19-data/scripts/src/cowidev/vax/incremental/kosovo.py"", line 22, in read
    soup = get_soup(self.source_url, verify=False)
  File ""/home/owid/covid-19-data/scripts/src/cowidev/utils/web/scraping.py"", line 83, in get_soup
    response = get_response(source, request_method, use_proxy, **kwargs)
  File ""/home/owid/covid-19-data/scripts/src/cowidev/utils/web/scraping.py"", line 52, in get_response
    raise ValueError(
ValueError: Source https://msh.rks-gov.net/sq/statistikat-covid-19/ not reached! Error code 404 Not Found
",Source https://msh.rks-gov.net/sq/statistikat-covid-19/ not reached! Error code 404 Not Found
cowidev.vax.incremental.kyrgyzstan,5.14,True,2023-03-23T07:00:24,,
cowidev.vax.incremental.laos,1.73,True,2023-03-23T07:03:03,,
cowidev.vax.incremental.macao,13.18,True,2023-03-23T07:00:32,,
cowidev.vax.incremental.moldova,,,2023-03-23T07:00:20,,
cowidev.vax.incremental.monaco,81.33,True,2023-03-23T07:01:41,,
cowidev.vax.incremental.mongolia,1.03,True,2023-03-23T07:00:22,,
cowidev.vax.incremental.montenegro,1.14,True,2023-03-23T07:00:22,,
cowidev.vax.incremental.morocco,,,2023-03-23T07:00:21,,
cowidev.vax.incremental.myanmar,,,2023-03-23T07:00:21,,
cowidev.vax.incremental.nepal,,,2023-03-23T07:00:21,,
cowidev.vax.incremental.north_macedonia,,,2023-03-23T07:00:21,,
cowidev.vax.incremental.northern_cyprus,2.95,True,2023-03-23T07:00:24,,
cowidev.vax.incremental.paho,82.82,False,2023-03-23T07:04:26,"Traceback (most recent call last):
  File ""/home/owid/covid-19-data/scripts/src/cowidev/cmd/commons/get.py"", line 47, in run
    module.main()
  File ""/home/owid/covid-19-data/scripts/src/cowidev/vax/incremental/paho.py"", line 195, in main
    PAHO().export()
  File ""/home/owid/covid-19-data/scripts/src/cowidev/vax/incremental/paho.py"", line 190, in export
    df = self.read().pipe(self.pipeline)
  File ""/home/owid/covid-19-data/scripts/venv/lib/python3.10/site-packages/pandas/core/generic.py"", line 5430, in pipe
    return com.pipe(self, func, *args, **kwargs)
  File ""/home/owid/covid-19-data/scripts/venv/lib/python3.10/site-packages/pandas/core/common.py"", line 471, in pipe
    return func(obj, *args, **kwargs)
  File ""/home/owid/covid-19-data/scripts/src/cowidev/vax/incremental/paho.py"", line 167, in pipeline
    df.pipe(self.pipe_check_columns)
  File ""/home/owid/covid-19-data/scripts/venv/lib/python3.10/site-packages/pandas/core/generic.py"", line 5430, in pipe
    return com.pipe(self, func, *args, **kwargs)
  File ""/home/owid/covid-19-data/scripts/venv/lib/python3.10/site-packages/pandas/core/common.py"", line 471, in pipe
    return func(obj, *args, **kwargs)
  File ""/home/owid/covid-19-data/scripts/src/cowidev/vax/incremental/paho.py"", line 122, in pipe_check_columns
    raise ValueError(f""Missing column fields: {columns_missing}. Present columns are: {df.columns}"")
ValueError: Missing column fields: {'Single dose', 'Country code', 'Country/ Territory', 'Second dose', '2nd additional dose', 'First dose', '1st additional dose', 'Total doses'}. Present columns are: Index(['date,location,total_vaccinations,people_vaccinated,people_fully_vaccinated,total_boosters,new_vaccinations,new_vaccinations_interpolated,new_people_vaccinated_interpolated,new_vaccinations_smoothed,new_people_vaccinated_smoothed', 'date'], dtype='object')
","Missing column fields: {'Single dose', 'Country code', 'Country/ Territory', 'Second dose', '2nd additional dose', 'First dose', '1st additional dose', 'Total doses'}. Present columns are: Index(['date,location,total_vaccinations,people_vaccinated,people_fully_vaccinated,total_boosters,new_vaccinations,new_vaccinations_interpolated,new_people_vaccinated_interpolated,new_vaccinations_smoothed,new_people_vaccinated_smoothed', 'date'], dtype='object')"
cowidev.vax.incremental.pakistan,,,2023-03-23T07:00:22,,
cowidev.vax.incremental.philippines,,,2023-03-23T07:00:22,,
cowidev.vax.incremental.poland,1.6,True,2023-03-23T07:00:24,,
cowidev.vax.incremental.qatar,,,2023-03-23T07:00:22,,
cowidev.vax.incremental.russia,18.31,True,2023-03-23T07:00:41,,
cowidev.vax.incremental.saint_lucia,,,2023-03-23T07:00:23,,
cowidev.vax.incremental.serbia,9.94,True,2023-03-23T07:00:32,,
cowidev.vax.incremental.south_africa,,,2023-03-23T07:00:23,,
cowidev.vax.incremental.spain,13.71,True,2023-03-23T07:00:36,,
cowidev.vax.incremental.sri_lanka,,,2023-03-23T07:00:23,,
cowidev.vax.incremental.suriname,14.0,True,2023-03-23T07:00:37,,
cowidev.vax.incremental.taiwan,17.31,True,2023-03-23T07:00:40,,
cowidev.vax.incremental.thailand,6.58,True,2023-03-23T07:00:30,,
cowidev.vax.incremental.turkey,10.01,False,2023-03-23T07:04:36,"Traceback (most recent call last):
  File ""/home/owid/covid-19-data/scripts/venv/lib/python3.10/site-packages/urllib3/connection.py"", line 174, in _new_conn
    conn = connection.create_connection(
  File ""/home/owid/covid-19-data/scripts/venv/lib/python3.10/site-packages/urllib3/util/connection.py"", line 72, in create_connection
    for res in socket.getaddrinfo(host, port, family, socket.SOCK_STREAM):
  File ""/usr/lib/python3.10/socket.py"", line 955, in getaddrinfo
    for res in _socket.getaddrinfo(host, port, family, type, proto, flags):
socket.gaierror: [Errno -3] Temporary failure in name resolution

During handling of the above exception, another exception occurred:

Traceback (most recent call last):
  File ""/home/owid/covid-19-data/scripts/venv/lib/python3.10/site-packages/urllib3/connectionpool.py"", line 703, in urlopen
    httplib_response = self._make_request(
  File ""/home/owid/covid-19-data/scripts/venv/lib/python3.10/site-packages/urllib3/connectionpool.py"", line 386, in _make_request
    self._validate_conn(conn)
  File ""/home/owid/covid-19-data/scripts/venv/lib/python3.10/site-packages/urllib3/connectionpool.py"", line 1042, in _validate_conn
    conn.connect()
  File ""/home/owid/covid-19-data/scripts/venv/lib/python3.10/site-packages/urllib3/connection.py"", line 358, in connect
    self.sock = conn = self._new_conn()
  File ""/home/owid/covid-19-data/scripts/venv/lib/python3.10/site-packages/urllib3/connection.py"", line 186, in _new_conn
    raise NewConnectionError(
urllib3.exceptions.NewConnectionError: <urllib3.connection.HTTPSConnection object at 0x7fc0d84ca200>: Failed to establish a new connection: [Errno -3] Temporary failure in name resolution

During handling of the above exception, another exception occurred:

Traceback (most recent call last):
  File ""/home/owid/covid-19-data/scripts/venv/lib/python3.10/site-packages/requests/adapters.py"", line 440, in send
    resp = conn.urlopen(
  File ""/home/owid/covid-19-data/scripts/venv/lib/python3.10/site-packages/urllib3/connectionpool.py"", line 787, in urlopen
    retries = retries.increment(
  File ""/home/owid/covid-19-data/scripts/venv/lib/python3.10/site-packages/urllib3/util/retry.py"", line 592, in increment
    raise MaxRetryError(_pool, url, error or ResponseError(cause))
urllib3.exceptions.MaxRetryError: HTTPSConnectionPool(host='covid19asi.saglik.gov.tr', port=443): Max retries exceeded with url: / (Caused by NewConnectionError('<urllib3.connection.HTTPSConnection object at 0x7fc0d84ca200>: Failed to establish a new connection: [Errno -3] Temporary failure in name resolution'))

During handling of the above exception, another exception occurred:

Traceback (most recent call last):
  File ""/home/owid/covid-19-data/scripts/src/cowidev/cmd/commons/get.py"", line 47, in run
    module.main()
  File ""/home/owid/covid-19-data/scripts/src/cowidev/vax/incremental/turkey.py"", line 60, in main
    data = read(source).pipe(pipeline)
  File ""/home/owid/covid-19-data/scripts/src/cowidev/vax/incremental/turkey.py"", line 19, in read
    soup = get_soup(source)
  File ""/home/owid/covid-19-data/scripts/src/cowidev/utils/web/scraping.py"", line 83, in get_soup
    response = get_response(source, request_method, use_proxy, **kwargs)
  File ""/home/owid/covid-19-data/scripts/src/cowidev/utils/web/scraping.py"", line 49, in get_response
    raise err
  File ""/home/owid/covid-19-data/scripts/src/cowidev/utils/web/scraping.py"", line 43, in get_response
    response = requests.get(source, **kwargs)
  File ""/home/owid/covid-19-data/scripts/venv/lib/python3.10/site-packages/requests/api.py"", line 75, in get
    return request('get', url, params=params, **kwargs)
  File ""/home/owid/covid-19-data/scripts/venv/lib/python3.10/site-packages/requests/api.py"", line 61, in request
    return session.request(method=method, url=url, **kwargs)
  File ""/home/owid/covid-19-data/scripts/venv/lib/python3.10/site-packages/requests/sessions.py"", line 529, in request
    resp = self.send(prep, **send_kwargs)
  File ""/home/owid/covid-19-data/scripts/venv/lib/python3.10/site-packages/requests/sessions.py"", line 645, in send
    r = adapter.send(request, **kwargs)
  File ""/home/owid/covid-19-data/scripts/venv/lib/python3.10/site-packages/requests/adapters.py"", line 519, in send
    raise ConnectionError(e, request=request)
requests.exceptions.ConnectionError: HTTPSConnectionPool(host='covid19asi.saglik.gov.tr', port=443): Max retries exceeded with url: / (Caused by NewConnectionError('<urllib3.connection.HTTPSConnection object at 0x7fc0d84ca200>: Failed to establish a new connection: [Errno -3] Temporary failure in name resolution'))
","HTTPSConnectionPool(host='covid19asi.saglik.gov.tr', port=443): Max retries exceeded with url: / (Caused by NewConnectionError('<urllib3.connection.HTTPSConnection object at 0x7fc0d84ca200>: Failed to establish a new connection: [Errno -3] Temporary failure in name resolution'))"
cowidev.vax.incremental.united_arab_emirates,,,2023-03-23T07:00:24,,
cowidev.vax.incremental.vietnam,,,2023-03-23T07:00:24,,
cowidev.vax.incremental.who,33.52,True,2023-03-23T07:00:57,,
cowidev.vax.incremental.zambia,2.21,True,2023-03-23T07:00:26,,
