module,execution_time (sec),success,timestamp,error,error_short
cowidev.vax.batch.argentina,14.98,True,2023-03-29T07:00:21,,
cowidev.vax.batch.australia,0.17,False,2023-03-29T07:01:48,"Traceback (most recent call last):
  File ""/home/owid/covid-19-data/scripts/src/cowidev/cmd/commons/get.py"", line 47, in run
    module.main()
  File ""/home/owid/covid-19-data/scripts/src/cowidev/vax/batch/australia.py"", line 244, in main
    Australia().export()
  File ""/home/owid/covid-19-data/scripts/src/cowidev/vax/batch/australia.py"", line 216, in export
    df = self.read().pipe(self.pipeline)  # Use with attach=False
  File ""/home/owid/covid-19-data/scripts/venv/lib/python3.10/site-packages/pandas/core/generic.py"", line 5430, in pipe
    return com.pipe(self, func, *args, **kwargs)
  File ""/home/owid/covid-19-data/scripts/venv/lib/python3.10/site-packages/pandas/core/common.py"", line 471, in pipe
    return func(obj, *args, **kwargs)
  File ""/home/owid/covid-19-data/scripts/src/cowidev/vax/batch/australia.py"", line 160, in pipeline
    .pipe(self.make_monotonic)
  File ""/home/owid/covid-19-data/scripts/venv/lib/python3.10/site-packages/pandas/core/generic.py"", line 5430, in pipe
    return com.pipe(self, func, *args, **kwargs)
  File ""/home/owid/covid-19-data/scripts/venv/lib/python3.10/site-packages/pandas/core/common.py"", line 471, in pipe
    return func(obj, *args, **kwargs)
  File ""/home/owid/covid-19-data/scripts/src/cowidev/vax/utils/base.py"", line 120, in make_monotonic
    return mkm(
  File ""/home/owid/covid-19-data/scripts/src/cowidev/utils/utils.py"", line 23, in make_monotonic
    return make_monotonic_new(df, column_date, column_metrics, max_removed_rows)
  File ""/home/owid/covid-19-data/scripts/src/cowidev/utils/utils.py"", line 94, in make_monotonic_new
    raise Exception(
Exception: 1 chunks of lengths 19 have been NaNed for metric people_vaccinated. That is more than maximum allowed (10) by make_monotonic() - check the data. Check dates ['2023-03-16']
",1 chunks of lengths 19 have been NaNed for metric people_vaccinated. That is more than maximum allowed (10) by make_monotonic() - check the data. Check dates ['2023-03-16']
cowidev.vax.batch.austria_old,,,2023-03-29T07:00:06,,
cowidev.vax.batch.belgium,10.13,True,2023-03-29T07:00:16,,
cowidev.vax.batch.bolivia,4.41,True,2023-03-29T07:00:11,,
cowidev.vax.batch.canada,5.39,False,2023-03-29T07:01:53,"Traceback (most recent call last):
  File ""/home/owid/covid-19-data/scripts/src/cowidev/cmd/commons/get.py"", line 47, in run
    module.main()
  File ""/home/owid/covid-19-data/scripts/src/cowidev/vax/batch/canada.py"", line 282, in main
    Canada().export()
  File ""/home/owid/covid-19-data/scripts/src/cowidev/vax/batch/canada.py"", line 270, in export
    df = df.pipe(self.pipeline, df_man)
  File ""/home/owid/covid-19-data/scripts/venv/lib/python3.10/site-packages/pandas/core/generic.py"", line 5430, in pipe
    return com.pipe(self, func, *args, **kwargs)
  File ""/home/owid/covid-19-data/scripts/venv/lib/python3.10/site-packages/pandas/core/common.py"", line 471, in pipe
    return func(obj, *args, **kwargs)
  File ""/home/owid/covid-19-data/scripts/src/cowidev/vax/batch/canada.py"", line 250, in pipeline
    .pipe(self.pipe_make_monotonic)[
  File ""/home/owid/covid-19-data/scripts/venv/lib/python3.10/site-packages/pandas/core/generic.py"", line 5430, in pipe
    return com.pipe(self, func, *args, **kwargs)
  File ""/home/owid/covid-19-data/scripts/venv/lib/python3.10/site-packages/pandas/core/common.py"", line 471, in pipe
    return func(obj, *args, **kwargs)
  File ""/home/owid/covid-19-data/scripts/src/cowidev/vax/batch/canada.py"", line 230, in pipe_make_monotonic
    df = df.pipe(self.make_monotonic, max_removed_rows=self.max_removed_rows)
  File ""/home/owid/covid-19-data/scripts/venv/lib/python3.10/site-packages/pandas/core/generic.py"", line 5430, in pipe
    return com.pipe(self, func, *args, **kwargs)
  File ""/home/owid/covid-19-data/scripts/venv/lib/python3.10/site-packages/pandas/core/common.py"", line 471, in pipe
    return func(obj, *args, **kwargs)
  File ""/home/owid/covid-19-data/scripts/src/cowidev/vax/utils/base.py"", line 120, in make_monotonic
    return mkm(
  File ""/home/owid/covid-19-data/scripts/src/cowidev/utils/utils.py"", line 23, in make_monotonic
    return make_monotonic_new(df, column_date, column_metrics, max_removed_rows)
  File ""/home/owid/covid-19-data/scripts/src/cowidev/utils/utils.py"", line 94, in make_monotonic_new
    raise Exception(
Exception: 1 chunks of lengths 36 have been NaNed for metric people_vaccinated. That is more than maximum allowed (22) by make_monotonic() - check the data. Check dates ['2023-01-26']
",1 chunks of lengths 36 have been NaNed for metric people_vaccinated. That is more than maximum allowed (22) by make_monotonic() - check the data. Check dates ['2023-01-26']
cowidev.vax.batch.chile,0.81,True,2023-03-29T07:00:07,,
cowidev.vax.batch.czechia,35.11,True,2023-03-29T07:00:41,,
cowidev.vax.batch.denmark,0.43,False,2023-03-29T07:01:54,"Traceback (most recent call last):
  File ""/home/owid/covid-19-data/scripts/src/cowidev/cmd/commons/get.py"", line 47, in run
    module.main()
  File ""/home/owid/covid-19-data/scripts/src/cowidev/vax/batch/denmark.py"", line 245, in main
    Denmark().export()
  File ""/home/owid/covid-19-data/scripts/src/cowidev/vax/batch/denmark.py"", line 226, in export
    df = self.read(index).pipe(self.pipeline, df_current).pipe(self.make_monotonic)
  File ""/home/owid/covid-19-data/scripts/src/cowidev/vax/batch/denmark.py"", line 43, in read
    url = self._parse_link_zip()
  File ""/home/owid/covid-19-data/scripts/src/cowidev/vax/batch/denmark.py"", line 67, in _parse_link_zip
    url = soup.find(""a"", string=""Download her"").get(""href"")
AttributeError: 'NoneType' object has no attribute 'get'
",'NoneType' object has no attribute 'get'
cowidev.vax.batch.ecdc,85.25,True,2023-03-29T07:01:31,,
cowidev.vax.batch.ecuador,,,2023-03-29T07:00:06,,
cowidev.vax.batch.estonia,0.58,True,2023-03-29T07:00:07,,
cowidev.vax.batch.france,7.83,True,2023-03-29T07:00:14,,
cowidev.vax.batch.germany,0.2,True,2023-03-29T07:00:06,,
cowidev.vax.batch.greece,14.12,True,2023-03-29T07:00:20,,
cowidev.vax.batch.hong_kong,16.57,True,2023-03-29T07:00:23,,
cowidev.vax.batch.indonesia,,,2023-03-29T07:00:06,,
cowidev.vax.batch.ireland,3.97,True,2023-03-29T07:00:10,,
cowidev.vax.batch.israel,9.66,True,2023-03-29T07:00:16,,
cowidev.vax.batch.italy,8.88,True,2023-03-29T07:00:15,,
cowidev.vax.batch.japan,36.83,True,2023-03-29T07:00:43,,
cowidev.vax.batch.jersey,5.11,True,2023-03-29T07:00:11,,
cowidev.vax.batch.latvia,64.82,True,2023-03-29T07:01:11,,
cowidev.vax.batch.lithuania,5.57,True,2023-03-29T07:00:12,,
cowidev.vax.batch.luxembourg,2.78,True,2023-03-29T07:00:09,,
cowidev.vax.batch.malaysia,1.06,True,2023-03-29T07:00:07,,
cowidev.vax.batch.malta,1.21,True,2023-03-29T07:00:07,,
cowidev.vax.batch.netherlands,,,2023-03-29T07:00:06,,
cowidev.vax.batch.new_zealand,16.26,True,2023-03-29T07:00:22,,
cowidev.vax.batch.norway,0.83,True,2023-03-29T07:00:07,,
cowidev.vax.batch.peru,4.91,True,2023-03-29T07:00:11,,
cowidev.vax.batch.portugal,,,2023-03-29T07:00:06,,
cowidev.vax.batch.romania,35.51,True,2023-03-29T07:00:42,,
cowidev.vax.batch.saudi_arabia,9.24,True,2023-03-29T07:00:15,,
cowidev.vax.batch.singapore,4.63,True,2023-03-29T07:00:11,,
cowidev.vax.batch.slovakia,45.8,True,2023-03-29T07:00:52,,
cowidev.vax.batch.slovenia,3.22,True,2023-03-29T07:00:10,,
cowidev.vax.batch.south_korea,60.68,False,2023-03-29T07:02:54,"Traceback (most recent call last):
  File ""/home/owid/covid-19-data/scripts/src/cowidev/cmd/commons/get.py"", line 47, in run
    module.main()
  File ""/home/owid/covid-19-data/scripts/src/cowidev/vax/batch/south_korea.py"", line 209, in main
    SouthKorea().export()
  File ""/home/owid/covid-19-data/scripts/src/cowidev/vax/batch/south_korea.py"", line 191, in export
    df_base = self.read().pipe(self.pipeline_base)
  File ""/home/owid/covid-19-data/scripts/src/cowidev/vax/batch/south_korea.py"", line 43, in read
    dfs = pd.read_html(to_proxy_url(self.source_url), encoding=""utf-8"")
  File ""/home/owid/covid-19-data/scripts/venv/lib/python3.10/site-packages/pandas/util/_decorators.py"", line 311, in wrapper
    return func(*args, **kwargs)
  File ""/home/owid/covid-19-data/scripts/venv/lib/python3.10/site-packages/pandas/io/html.py"", line 1098, in read_html
    return _parse(
  File ""/home/owid/covid-19-data/scripts/venv/lib/python3.10/site-packages/pandas/io/html.py"", line 906, in _parse
    tables = p.parse_tables()
  File ""/home/owid/covid-19-data/scripts/venv/lib/python3.10/site-packages/pandas/io/html.py"", line 222, in parse_tables
    tables = self._parse_tables(self._build_doc(), self.match, self.attrs)
  File ""/home/owid/covid-19-data/scripts/venv/lib/python3.10/site-packages/pandas/io/html.py"", line 745, in _build_doc
    raise e
  File ""/home/owid/covid-19-data/scripts/venv/lib/python3.10/site-packages/pandas/io/html.py"", line 726, in _build_doc
    with urlopen(self.io) as f:
  File ""/home/owid/covid-19-data/scripts/venv/lib/python3.10/site-packages/pandas/io/common.py"", line 212, in urlopen
    return urllib.request.urlopen(*args, **kwargs)
  File ""/usr/lib/python3.10/urllib/request.py"", line 216, in urlopen
    return opener.open(url, data, timeout)
  File ""/usr/lib/python3.10/urllib/request.py"", line 525, in open
    response = meth(req, response)
  File ""/usr/lib/python3.10/urllib/request.py"", line 634, in http_response
    response = self.parent.error(
  File ""/usr/lib/python3.10/urllib/request.py"", line 563, in error
    return self._call_chain(*args)
  File ""/usr/lib/python3.10/urllib/request.py"", line 496, in _call_chain
    result = func(*args)
  File ""/usr/lib/python3.10/urllib/request.py"", line 643, in http_error_default
    raise HTTPError(req.full_url, code, msg, hdrs, fp)
urllib.error.HTTPError: HTTP Error 500: Internal Server Error
",HTTP Error 500: Internal Server Error
cowidev.vax.batch.spc,24.68,True,2023-03-29T07:00:32,,
cowidev.vax.batch.sweden,12.88,True,2023-03-29T07:00:20,,
cowidev.vax.batch.switzerland,82.92,True,2023-03-29T07:01:30,,
cowidev.vax.batch.trinidad_and_tobago,4.96,True,2023-03-29T07:00:12,,
cowidev.vax.batch.ukraine,,,2023-03-29T07:00:09,,
cowidev.vax.batch.united_kingdom,13.42,True,2023-03-29T07:00:22,,
cowidev.vax.batch.united_states,82.67,True,2023-03-29T07:01:32,,
cowidev.vax.batch.uruguay,6.3,True,2023-03-29T07:00:16,,
cowidev.vax.batch.zimbabwe,2.08,True,2023-03-29T07:00:12,,
cowidev.vax.incremental.africacdc,,,2023-03-29T07:00:11,,
cowidev.vax.incremental.antigua_barbuda,,,2023-03-29T07:00:11,,
cowidev.vax.incremental.aruba,2.13,True,2023-03-29T07:00:13,,
cowidev.vax.incremental.austria,,,2023-03-29T07:00:11,,
cowidev.vax.incremental.azerbaijan,,,2023-03-29T07:00:11,,
cowidev.vax.incremental.bahrain,,,2023-03-29T07:00:11,,
cowidev.vax.incremental.bangladesh,34.61,False,2023-03-29T07:03:29,"Traceback (most recent call last):
  File ""/home/owid/covid-19-data/scripts/venv/lib/python3.10/site-packages/urllib3/response.py"", line 443, in _error_catcher
    yield
  File ""/home/owid/covid-19-data/scripts/venv/lib/python3.10/site-packages/urllib3/response.py"", line 815, in read_chunked
    self._update_chunk_length()
  File ""/home/owid/covid-19-data/scripts/venv/lib/python3.10/site-packages/urllib3/response.py"", line 745, in _update_chunk_length
    line = self._fp.fp.readline()
  File ""/usr/lib/python3.10/socket.py"", line 705, in readinto
    return self._sock.recv_into(b)
TimeoutError: timed out

During handling of the above exception, another exception occurred:

Traceback (most recent call last):
  File ""/home/owid/covid-19-data/scripts/venv/lib/python3.10/site-packages/requests/models.py"", line 760, in generate
    for chunk in self.raw.stream(chunk_size, decode_content=True):
  File ""/home/owid/covid-19-data/scripts/venv/lib/python3.10/site-packages/urllib3/response.py"", line 623, in stream
    for line in self.read_chunked(amt, decode_content=decode_content):
  File ""/home/owid/covid-19-data/scripts/venv/lib/python3.10/site-packages/urllib3/response.py"", line 803, in read_chunked
    with self._error_catcher():
  File ""/usr/lib/python3.10/contextlib.py"", line 153, in __exit__
    self.gen.throw(typ, value, traceback)
  File ""/home/owid/covid-19-data/scripts/venv/lib/python3.10/site-packages/urllib3/response.py"", line 448, in _error_catcher
    raise ReadTimeoutError(self._pool, None, ""Read timed out."")
urllib3.exceptions.ReadTimeoutError: HTTPConnectionPool(host='103.247.238.92', port=80): Read timed out.

During handling of the above exception, another exception occurred:

Traceback (most recent call last):
  File ""/home/owid/covid-19-data/scripts/src/cowidev/cmd/commons/get.py"", line 47, in run
    module.main()
  File ""/home/owid/covid-19-data/scripts/src/cowidev/vax/incremental/bangladesh.py"", line 112, in main
    Bangladesh().export()
  File ""/home/owid/covid-19-data/scripts/src/cowidev/vax/incremental/bangladesh.py"", line 98, in export
    data = self.read().pipe(self.pipeline)
  File ""/home/owid/covid-19-data/scripts/src/cowidev/vax/incremental/bangladesh.py"", line 25, in read
    metrics = self._parse_metrics(soup)
  File ""/home/owid/covid-19-data/scripts/src/cowidev/vax/incremental/bangladesh.py"", line 74, in _parse_metrics
    single_doses = self._parse_single_doses()
  File ""/home/owid/covid-19-data/scripts/src/cowidev/vax/incremental/bangladesh.py"", line 38, in _parse_single_doses
    soup = get_soup(url, timeout=30)
  File ""/home/owid/covid-19-data/scripts/src/cowidev/utils/web/scraping.py"", line 83, in get_soup
    response = get_response(source, request_method, use_proxy, **kwargs)
  File ""/home/owid/covid-19-data/scripts/src/cowidev/utils/web/scraping.py"", line 49, in get_response
    raise err
  File ""/home/owid/covid-19-data/scripts/src/cowidev/utils/web/scraping.py"", line 43, in get_response
    response = requests.get(source, **kwargs)
  File ""/home/owid/covid-19-data/scripts/venv/lib/python3.10/site-packages/requests/api.py"", line 75, in get
    return request('get', url, params=params, **kwargs)
  File ""/home/owid/covid-19-data/scripts/venv/lib/python3.10/site-packages/requests/api.py"", line 61, in request
    return session.request(method=method, url=url, **kwargs)
  File ""/home/owid/covid-19-data/scripts/venv/lib/python3.10/site-packages/requests/sessions.py"", line 529, in request
    resp = self.send(prep, **send_kwargs)
  File ""/home/owid/covid-19-data/scripts/venv/lib/python3.10/site-packages/requests/sessions.py"", line 687, in send
    r.content
  File ""/home/owid/covid-19-data/scripts/venv/lib/python3.10/site-packages/requests/models.py"", line 838, in content
    self._content = b''.join(self.iter_content(CONTENT_CHUNK_SIZE)) or b''
  File ""/home/owid/covid-19-data/scripts/venv/lib/python3.10/site-packages/requests/models.py"", line 767, in generate
    raise ConnectionError(e)
requests.exceptions.ConnectionError: HTTPConnectionPool(host='103.247.238.92', port=80): Read timed out.
","HTTPConnectionPool(host='103.247.238.92', port=80): Read timed out."
cowidev.vax.incremental.barbados,,,2023-03-29T07:00:11,,
cowidev.vax.incremental.brazil,2.37,True,2023-03-29T07:00:14,,
cowidev.vax.incremental.bulgaria,8.37,True,2023-03-29T07:00:20,,
cowidev.vax.incremental.china,18.52,True,2023-03-29T07:00:30,,
cowidev.vax.incremental.costa_rica,,,2023-03-29T07:00:12,,
cowidev.vax.incremental.croatia,2.03,True,2023-03-29T07:00:14,,
cowidev.vax.incremental.cuba,8.84,True,2023-03-29T07:00:21,,
cowidev.vax.incremental.curacao,1.66,True,2023-03-29T07:00:14,,
cowidev.vax.incremental.cyprus,1.99,True,2023-03-29T07:00:16,,
cowidev.vax.incremental.dominican_republic,11.31,False,2023-03-29T07:03:40,"Traceback (most recent call last):
  File ""/home/owid/covid-19-data/scripts/src/cowidev/cmd/commons/get.py"", line 47, in run
    module.main()
  File ""/home/owid/covid-19-data/scripts/src/cowidev/vax/incremental/dominican_republic.py"", line 113, in main
    DominicanRepublic().export()
  File ""/home/owid/covid-19-data/scripts/src/cowidev/vax/incremental/dominican_republic.py"", line 68, in export
    data = self.read().pipe(self.pipeline)
  File ""/home/owid/covid-19-data/scripts/src/cowidev/vax/incremental/dominican_republic.py"", line 26, in read
    metrics = self._parse_metrics(driver)
  File ""/home/owid/covid-19-data/scripts/src/cowidev/vax/incremental/dominican_republic.py"", line 35, in _parse_metrics
    metric_candidates = _find_potential_metrics(driver)
  File ""/home/owid/covid-19-data/scripts/src/cowidev/vax/incremental/dominican_republic.py"", line 92, in _find_potential_metrics
    h3 = _find_h3(driver)
  File ""/home/owid/covid-19-data/scripts/src/cowidev/vax/incremental/dominican_republic.py"", line 82, in _find_h3
    raise ValueError(""More than one element found!"")
ValueError: More than one element found!
",More than one element found!
cowidev.vax.incremental.el_salvador,8.99,True,2023-03-29T07:00:23,,
cowidev.vax.incremental.faeroe_islands,1.05,True,2023-03-29T07:00:15,,
cowidev.vax.incremental.fiji,0.0,True,2023-03-29T07:00:15,,
cowidev.vax.incremental.finland,0.56,True,2023-03-29T07:00:16,,
cowidev.vax.incremental.gabon,,,2023-03-29T07:00:15,,
cowidev.vax.incremental.georgia,5.65,True,2023-03-29T07:00:21,,
cowidev.vax.incremental.greenland,0.09,False,2023-03-29T07:03:40,"Traceback (most recent call last):
  File ""/home/owid/covid-19-data/scripts/src/cowidev/cmd/commons/get.py"", line 47, in run
    module.main()
  File ""/home/owid/covid-19-data/scripts/src/cowidev/vax/incremental/greenland.py"", line 76, in main
    Greenland().export()
  File ""/home/owid/covid-19-data/scripts/src/cowidev/vax/incremental/greenland.py"", line 63, in export
    data = self.read().pipe(self.pipeline)
  File ""/home/owid/covid-19-data/scripts/src/cowidev/vax/incremental/greenland.py"", line 17, in read
    data = self._parse_data(soup)
  File ""/home/owid/covid-19-data/scripts/src/cowidev/vax/incremental/greenland.py"", line 21, in _parse_data
    return {**self._parse_data_metrics(soup), **self._parse_data_date(soup)}
  File ""/home/owid/covid-19-data/scripts/src/cowidev/vax/incremental/greenland.py"", line 31, in _parse_data_metrics
    assert len(counter_1) == len(counter_2) == 1
AssertionError
",
cowidev.vax.incremental.guatemala,,,2023-03-29T07:00:16,,
cowidev.vax.incremental.guernsey,7.87,True,2023-03-29T07:00:23,,
cowidev.vax.incremental.hungary,74.78,True,2023-03-29T07:01:30,,
cowidev.vax.incremental.iceland,1.74,True,2023-03-29T07:00:18,,
cowidev.vax.incremental.india,4.94,True,2023-03-29T07:00:21,,
cowidev.vax.incremental.iran,,,2023-03-29T07:00:16,,
cowidev.vax.incremental.isle_of_man,2.96,True,2023-03-29T07:00:19,,
cowidev.vax.incremental.jamaica,7.91,True,2023-03-29T07:00:25,,
cowidev.vax.incremental.kazakhstan,9.06,True,2023-03-29T07:00:27,,
cowidev.vax.incremental.kosovo,0.12,False,2023-03-29T07:03:40,"Traceback (most recent call last):
  File ""/home/owid/covid-19-data/scripts/src/cowidev/cmd/commons/get.py"", line 47, in run
    module.main()
  File ""/home/owid/covid-19-data/scripts/src/cowidev/vax/incremental/kosovo.py"", line 82, in main
    Kosovo().export()
  File ""/home/owid/covid-19-data/scripts/src/cowidev/vax/incremental/kosovo.py"", line 77, in export
    df = self.read().pipe(self.pipeline)
  File ""/home/owid/covid-19-data/scripts/src/cowidev/vax/incremental/kosovo.py"", line 22, in read
    soup = get_soup(self.source_url, verify=False)
  File ""/home/owid/covid-19-data/scripts/src/cowidev/utils/web/scraping.py"", line 83, in get_soup
    response = get_response(source, request_method, use_proxy, **kwargs)
  File ""/home/owid/covid-19-data/scripts/src/cowidev/utils/web/scraping.py"", line 52, in get_response
    raise ValueError(
ValueError: Source https://msh.rks-gov.net/sq/statistikat-covid-19/ not reached! Error code 404 Not Found
",Source https://msh.rks-gov.net/sq/statistikat-covid-19/ not reached! Error code 404 Not Found
cowidev.vax.incremental.kyrgyzstan,4.98,True,2023-03-29T07:00:25,,
cowidev.vax.incremental.laos,1.66,True,2023-03-29T07:03:42,,
cowidev.vax.incremental.macao,13.77,True,2023-03-29T07:00:34,,
cowidev.vax.incremental.moldova,,,2023-03-29T07:00:21,,
cowidev.vax.incremental.monaco,84.73,True,2023-03-29T07:01:46,,
cowidev.vax.incremental.mongolia,1.15,True,2023-03-29T07:00:22,,
cowidev.vax.incremental.montenegro,1.02,True,2023-03-29T07:00:22,,
cowidev.vax.incremental.morocco,,,2023-03-29T07:00:21,,
cowidev.vax.incremental.myanmar,,,2023-03-29T07:00:21,,
cowidev.vax.incremental.nepal,,,2023-03-29T07:00:21,,
cowidev.vax.incremental.north_macedonia,,,2023-03-29T07:00:21,,
cowidev.vax.incremental.northern_cyprus,3.63,True,2023-03-29T07:00:25,,
cowidev.vax.incremental.paho,81.76,False,2023-03-29T07:05:04,"Traceback (most recent call last):
  File ""/home/owid/covid-19-data/scripts/src/cowidev/cmd/commons/get.py"", line 47, in run
    module.main()
  File ""/home/owid/covid-19-data/scripts/src/cowidev/vax/incremental/paho.py"", line 195, in main
    PAHO().export()
  File ""/home/owid/covid-19-data/scripts/src/cowidev/vax/incremental/paho.py"", line 190, in export
    df = self.read().pipe(self.pipeline)
  File ""/home/owid/covid-19-data/scripts/venv/lib/python3.10/site-packages/pandas/core/generic.py"", line 5430, in pipe
    return com.pipe(self, func, *args, **kwargs)
  File ""/home/owid/covid-19-data/scripts/venv/lib/python3.10/site-packages/pandas/core/common.py"", line 471, in pipe
    return func(obj, *args, **kwargs)
  File ""/home/owid/covid-19-data/scripts/src/cowidev/vax/incremental/paho.py"", line 167, in pipeline
    df.pipe(self.pipe_check_columns)
  File ""/home/owid/covid-19-data/scripts/venv/lib/python3.10/site-packages/pandas/core/generic.py"", line 5430, in pipe
    return com.pipe(self, func, *args, **kwargs)
  File ""/home/owid/covid-19-data/scripts/venv/lib/python3.10/site-packages/pandas/core/common.py"", line 471, in pipe
    return func(obj, *args, **kwargs)
  File ""/home/owid/covid-19-data/scripts/src/cowidev/vax/incremental/paho.py"", line 122, in pipe_check_columns
    raise ValueError(f""Missing column fields: {columns_missing}. Present columns are: {df.columns}"")
ValueError: Missing column fields: {'Second dose', 'First dose', 'Country code', '2nd additional dose', 'Total doses', 'Country/ Territory', '1st additional dose', 'Single dose'}. Present columns are: Index(['date,location,total_vaccinations,people_vaccinated,people_fully_vaccinated,total_boosters,new_vaccinations,new_vaccinations_interpolated,new_people_vaccinated_interpolated,new_vaccinations_smoothed,new_people_vaccinated_smoothed', 'date'], dtype='object')
","Missing column fields: {'Second dose', 'First dose', 'Country code', '2nd additional dose', 'Total doses', 'Country/ Territory', '1st additional dose', 'Single dose'}. Present columns are: Index(['date,location,total_vaccinations,people_vaccinated,people_fully_vaccinated,total_boosters,new_vaccinations,new_vaccinations_interpolated,new_people_vaccinated_interpolated,new_vaccinations_smoothed,new_people_vaccinated_smoothed', 'date'], dtype='object')"
cowidev.vax.incremental.pakistan,,,2023-03-29T07:00:22,,
cowidev.vax.incremental.philippines,,,2023-03-29T07:00:22,,
cowidev.vax.incremental.poland,1.26,True,2023-03-29T07:00:23,,
cowidev.vax.incremental.qatar,,,2023-03-29T07:00:22,,
cowidev.vax.incremental.russia,16.67,True,2023-03-29T07:00:39,,
cowidev.vax.incremental.saint_lucia,,,2023-03-29T07:00:22,,
cowidev.vax.incremental.serbia,9.16,True,2023-03-29T07:00:32,,
cowidev.vax.incremental.south_africa,,,2023-03-29T07:00:22,,
cowidev.vax.incremental.spain,16.04,True,2023-03-29T07:00:39,,
cowidev.vax.incremental.sri_lanka,,,2023-03-29T07:00:23,,
cowidev.vax.incremental.suriname,15.09,True,2023-03-29T07:00:38,,
cowidev.vax.incremental.taiwan,5.01,False,2023-03-29T07:05:09,"Traceback (most recent call last):
  File ""/home/owid/covid-19-data/scripts/venv/lib/python3.10/site-packages/urllib3/connection.py"", line 174, in _new_conn
    conn = connection.create_connection(
  File ""/home/owid/covid-19-data/scripts/venv/lib/python3.10/site-packages/urllib3/util/connection.py"", line 72, in create_connection
    for res in socket.getaddrinfo(host, port, family, socket.SOCK_STREAM):
  File ""/usr/lib/python3.10/socket.py"", line 955, in getaddrinfo
    for res in _socket.getaddrinfo(host, port, family, type, proto, flags):
socket.gaierror: [Errno -3] Temporary failure in name resolution

During handling of the above exception, another exception occurred:

Traceback (most recent call last):
  File ""/home/owid/covid-19-data/scripts/venv/lib/python3.10/site-packages/urllib3/connectionpool.py"", line 703, in urlopen
    httplib_response = self._make_request(
  File ""/home/owid/covid-19-data/scripts/venv/lib/python3.10/site-packages/urllib3/connectionpool.py"", line 386, in _make_request
    self._validate_conn(conn)
  File ""/home/owid/covid-19-data/scripts/venv/lib/python3.10/site-packages/urllib3/connectionpool.py"", line 1042, in _validate_conn
    conn.connect()
  File ""/home/owid/covid-19-data/scripts/venv/lib/python3.10/site-packages/urllib3/connection.py"", line 358, in connect
    self.sock = conn = self._new_conn()
  File ""/home/owid/covid-19-data/scripts/venv/lib/python3.10/site-packages/urllib3/connection.py"", line 186, in _new_conn
    raise NewConnectionError(
urllib3.exceptions.NewConnectionError: <urllib3.connection.HTTPSConnection object at 0x7f24ce5f1d50>: Failed to establish a new connection: [Errno -3] Temporary failure in name resolution

During handling of the above exception, another exception occurred:

Traceback (most recent call last):
  File ""/home/owid/covid-19-data/scripts/venv/lib/python3.10/site-packages/requests/adapters.py"", line 440, in send
    resp = conn.urlopen(
  File ""/home/owid/covid-19-data/scripts/venv/lib/python3.10/site-packages/urllib3/connectionpool.py"", line 787, in urlopen
    retries = retries.increment(
  File ""/home/owid/covid-19-data/scripts/venv/lib/python3.10/site-packages/urllib3/util/retry.py"", line 592, in increment
    raise MaxRetryError(_pool, url, error or ResponseError(cause))
urllib3.exceptions.MaxRetryError: HTTPSConnectionPool(host='www.cdc.gov.tw', port=443): Max retries exceeded with url: /Category/Page/9jFXNbCe-sFK9EImRRi2Og (Caused by NewConnectionError('<urllib3.connection.HTTPSConnection object at 0x7f24ce5f1d50>: Failed to establish a new connection: [Errno -3] Temporary failure in name resolution'))

During handling of the above exception, another exception occurred:

Traceback (most recent call last):
  File ""/home/owid/covid-19-data/scripts/src/cowidev/cmd/commons/get.py"", line 47, in run
    module.main()
  File ""/home/owid/covid-19-data/scripts/src/cowidev/vax/incremental/taiwan.py"", line 179, in main
    Taiwan().export()
  File ""/home/owid/covid-19-data/scripts/src/cowidev/vax/incremental/taiwan.py"", line 165, in export
    data = self.read().pipe(self.pipeline)
  File ""/home/owid/covid-19-data/scripts/src/cowidev/vax/incremental/taiwan.py"", line 32, in read
    soup = get_soup(self.source_data_url)
  File ""/home/owid/covid-19-data/scripts/src/cowidev/utils/web/scraping.py"", line 83, in get_soup
    response = get_response(source, request_method, use_proxy, **kwargs)
  File ""/home/owid/covid-19-data/scripts/src/cowidev/utils/web/scraping.py"", line 49, in get_response
    raise err
  File ""/home/owid/covid-19-data/scripts/src/cowidev/utils/web/scraping.py"", line 43, in get_response
    response = requests.get(source, **kwargs)
  File ""/home/owid/covid-19-data/scripts/venv/lib/python3.10/site-packages/requests/api.py"", line 75, in get
    return request('get', url, params=params, **kwargs)
  File ""/home/owid/covid-19-data/scripts/venv/lib/python3.10/site-packages/requests/api.py"", line 61, in request
    return session.request(method=method, url=url, **kwargs)
  File ""/home/owid/covid-19-data/scripts/venv/lib/python3.10/site-packages/requests/sessions.py"", line 529, in request
    resp = self.send(prep, **send_kwargs)
  File ""/home/owid/covid-19-data/scripts/venv/lib/python3.10/site-packages/requests/sessions.py"", line 645, in send
    r = adapter.send(request, **kwargs)
  File ""/home/owid/covid-19-data/scripts/venv/lib/python3.10/site-packages/requests/adapters.py"", line 519, in send
    raise ConnectionError(e, request=request)
requests.exceptions.ConnectionError: HTTPSConnectionPool(host='www.cdc.gov.tw', port=443): Max retries exceeded with url: /Category/Page/9jFXNbCe-sFK9EImRRi2Og (Caused by NewConnectionError('<urllib3.connection.HTTPSConnection object at 0x7f24ce5f1d50>: Failed to establish a new connection: [Errno -3] Temporary failure in name resolution'))
","HTTPSConnectionPool(host='www.cdc.gov.tw', port=443): Max retries exceeded with url: /Category/Page/9jFXNbCe-sFK9EImRRi2Og (Caused by NewConnectionError('<urllib3.connection.HTTPSConnection object at 0x7f24ce5f1d50>: Failed to establish a new connection: [Errno -3] Temporary failure in name resolution'))"
cowidev.vax.incremental.thailand,7.37,True,2023-03-29T07:00:31,,
cowidev.vax.incremental.turkey,6.19,False,2023-03-29T07:05:15,"Traceback (most recent call last):
  File ""/home/owid/covid-19-data/scripts/src/cowidev/cmd/commons/get.py"", line 47, in run
    module.main()
  File ""/home/owid/covid-19-data/scripts/src/cowidev/vax/incremental/turkey.py"", line 60, in main
    data = read(source).pipe(pipeline)
  File ""/home/owid/covid-19-data/scripts/src/cowidev/vax/incremental/turkey.py"", line 19, in read
    soup = get_soup(source)
  File ""/home/owid/covid-19-data/scripts/src/cowidev/utils/web/scraping.py"", line 83, in get_soup
    response = get_response(source, request_method, use_proxy, **kwargs)
  File ""/home/owid/covid-19-data/scripts/src/cowidev/utils/web/scraping.py"", line 52, in get_response
    raise ValueError(
ValueError: Source https://covid19asi.saglik.gov.tr/ not reached! Error code 504 Gateway Timeout
",Source https://covid19asi.saglik.gov.tr/ not reached! Error code 504 Gateway Timeout
cowidev.vax.incremental.united_arab_emirates,,,2023-03-29T07:00:23,,
cowidev.vax.incremental.vietnam,,,2023-03-29T07:00:23,,
cowidev.vax.incremental.who,29.89,True,2023-03-29T07:00:53,,
cowidev.vax.incremental.zambia,2.02,True,2023-03-29T07:00:27,,
